<?xml version="1.0"?>
<robot name="C:/Users/Erkan Ertugrul/Documents/GitHub/WebotsOtonomArac/arac.urdf" xmlns:xacro="http://ros.org/wiki/xacro">
  <link name="base_link">
    <visual>
      <origin xyz="2.6775 0 0.29" rpy="1.570796 0 1.570796"/>
      <geometry>
        <box size="1.73 0.76 2"/>
      </geometry>
    </visual>
    <collision>
      <origin xyz="2.6775 0 0.29" rpy="1.570796 0 1.570796"/>
      <geometry>
        <box size="1.73 0.76 2"/>
      </geometry>
    </collision>
    <visual>
      <origin xyz="0.5875 0 0.63" rpy="1.570796 0 1.570796"/>
      <geometry>
        <box size="1.73 1.44 2.14"/>
      </geometry>
    </visual>
    <collision>
      <origin xyz="0.5875 0 0.63" rpy="1.570796 0 1.570796"/>
      <geometry>
        <box size="1.73 1.44 2.14"/>
      </geometry>
    </collision>
    <visual>
      <origin xyz="-0.1725 0 0.53" rpy="1.570796 0 1.570796"/>
      <geometry>
        <box size="1.73 0.78 1.41"/>
      </geometry>
    </visual>
    <collision>
      <origin xyz="-0.1725 0 0.53" rpy="1.570796 0 1.570796"/>
      <geometry>
        <box size="1.73 0.78 1.41"/>
      </geometry>
    </collision>
  </link>
  <joint name="rpm_needle_motor" type="revolute">
    <parent link="base_link"/>
    <child link="rpm needle"/>
    <axis xyz="0.055 0 -0.049"/>
    <limit effort="10" lower="0" upper="4.42" velocity="10"/>
    <origin xyz="2.16 0.3389 0.7319" rpy="0 0 0"/>
  </joint>
  <link name="rpm needle">
  </link>
  <joint name="speed_needle_motor" type="revolute">
    <parent link="base_link"/>
    <child link="speed needle"/>
    <axis xyz="0.055 0 -0.049"/>
    <limit effort="10" lower="0" upper="4.42" velocity="10"/>
    <origin xyz="0 0.1746 -0.0011" rpy="0.002076 0.000002 -0.00185"/>
  </joint>
  <link name="speed needle">
  </link>
  <joint name="steering_wheel_motor" type="continuous">
    <parent link="base_link"/>
    <child link="vehicle steering wheel"/>
    <axis xyz="0 -0.88 2.6"/>
    <limit effort="10" velocity="10"/>
    <origin xyz="-0.13 -0.0835 -0.1208" rpy="2.117693 -1.139222 0.745214"/>
  </joint>
  <link name="vehicle steering wheel">
  </link>
  <joint name="indicator_lever_motor" type="revolute">
    <parent link="base_link"/>
    <child link="solid"/>
    <axis xyz="0 0 1"/>
    <limit effort="10" lower="-0.4" upper="0.4" velocity="100"/>
    <origin xyz="0.533 0.58 2.09" rpy="1.570796 0 1.570796"/>
  </joint>
  <link name="solid">
  </link>
  <joint name="left_wiper_motor" type="revolute">
    <parent link="base_link"/>
    <child link="left wiper"/>
    <axis xyz="-1.25 -0.08 -1.85"/>
    <limit effort="10" lower="0" upper="1.6" velocity="10"/>
    <origin xyz="1.88 -1.46 0.307" rpy="-0.509459 -0.266995 -0.824525"/>
  </joint>
  <link name="left wiper">
  </link>
  <joint name="right_wiper_motor" type="revolute">
    <parent link="base_link"/>
    <child link="right wiper"/>
    <axis xyz="-1.7 0.04 -2.19"/>
    <limit effort="10" lower="0" upper="1.6" velocity="10"/>
    <origin xyz="0.09 -0.58 -0.05" rpy="-0.58534 -0.232902 -0.787675"/>
  </joint>
  <link name="right wiper">
  </link>
  <link name="interior_left_indicators">
  </link>
  <joint name="base_link_interior_left_indicators_joint" type="fixed">
    <parent link="base_link"/>
    <child link="interior_left_indicators"/>
    <origin xyz="-2.55 -0.05 -0.79" rpy="0 0 0"/>
  </joint>
  <link name="interior_right_indicators">
  </link>
  <joint name="base_link_interior_right_indicators_joint" type="fixed">
    <parent link="base_link"/>
    <child link="interior_right_indicators"/>
    <origin xyz="0 0 0" rpy="0 0 0"/>
  </joint>
  <link name="backwards_lights">
  </link>
  <joint name="base_link_backwards_lights_joint" type="fixed">
    <parent link="base_link"/>
    <child link="backwards_lights"/>
    <origin xyz="0 0 0" rpy="0 0 0"/>
  </joint>
  <link name="rear_lights">
  </link>
  <joint name="base_link_rear_lights_joint" type="fixed">
    <parent link="base_link"/>
    <child link="rear_lights"/>
    <origin xyz="0 0 0" rpy="0 0 0"/>
  </joint>
  <link name="brake_lights">
  </link>
  <joint name="base_link_brake_lights_joint" type="fixed">
    <parent link="base_link"/>
    <child link="brake_lights"/>
    <origin xyz="0 0 0" rpy="0 0 0"/>
  </joint>
  <link name="antifog_lights">
  </link>
  <joint name="base_link_antifog_lights_joint" type="fixed">
    <parent link="base_link"/>
    <child link="antifog_lights"/>
    <origin xyz="0 0 0" rpy="0 0 0"/>
  </joint>
  <link name="left_indicators">
  </link>
  <joint name="base_link_left_indicators_joint" type="fixed">
    <parent link="base_link"/>
    <child link="left_indicators"/>
    <origin xyz="0 0 0" rpy="0 0 0"/>
  </joint>
  <link name="right_indicators">
  </link>
  <joint name="base_link_right_indicators_joint" type="fixed">
    <parent link="base_link"/>
    <child link="right_indicators"/>
    <origin xyz="0 0 0" rpy="0 0 0"/>
  </joint>
  <link name="front_lights">
  </link>
  <joint name="base_link_front_lights_joint" type="fixed">
    <parent link="base_link"/>
    <child link="front_lights"/>
    <origin xyz="0 0 0" rpy="0 0 0"/>
  </joint>
  <link name="display">
  </link>
  <joint name="base_link_display_joint" type="fixed">
    <parent link="base_link"/>
    <child link="display"/>
    <origin xyz="0 0 0" rpy="0 0 0"/>
  </joint>
  <link name="gyro">
  </link>
  <joint name="base_link_gyro_joint" type="fixed">
    <parent link="base_link"/>
    <child link="gyro"/>
    <origin xyz="0 0 0" rpy="0 0 0"/>
  </joint>
  <link name="gps">
  </link>
  <joint name="base_link_gps_joint" type="fixed">
    <parent link="base_link"/>
    <child link="gps"/>
    <origin xyz="0 0 0" rpy="0 0 0"/>
  </joint>
  <link name="camera">
  </link>
  <joint name="base_link_camera_joint" type="fixed">
    <parent link="base_link"/>
    <child link="camera"/>
    <origin xyz="1.72 0 1.4" rpy="-1.570796 0 -1.570796"/>
  </joint>
  <link name="compass">
  </link>
  <joint name="base_link_compass_joint" type="fixed">
    <parent link="base_link"/>
    <child link="compass"/>
    <origin xyz="1 0 1.45" rpy="0 0 0"/>
  </joint>
  <link name="Sick LMS 291">
  </link>
  <joint name="base_link_Sick LMS 291_joint" type="fixed">
    <parent link="base_link"/>
    <child link="Sick LMS 291"/>
    <origin xyz="3.91 0 0.45" rpy="0 0 0"/>
  </joint>
  <link name="ds0">
  </link>
  <joint name="base_link_ds0_joint" type="fixed">
    <parent link="base_link"/>
    <child link="ds0"/>
    <origin xyz="3.85 0 0.45" rpy="0 0 0"/>
  </joint>
  <link name="engine_speaker">
  </link>
  <joint name="base_link_engine_speaker_joint" type="fixed">
    <parent link="base_link"/>
    <child link="engine_speaker"/>
    <origin xyz="2.995 0 0" rpy="0 0 0"/>
  </joint>
  <joint name="right_rear_sensor" type="continuous">
    <parent link="base_link"/>
    <child link="rear right wheel"/>
    <axis xyz="0 1 0"/>
    <origin xyz="0 -0.814 0" rpy="0 1.217046 0"/>
  </joint>
  <link name="rear right wheel">
    <visual>
      <origin xyz="0 0 0" rpy="1.570796 0 0"/>
      <geometry>
        <cylinder radius="0.374" length="0.25"/>
      </geometry>
    </visual>
    <collision>
      <origin xyz="0 0 0" rpy="1.570796 0 0"/>
      <geometry>
        <cylinder radius="0.374" length="0.25"/>
      </geometry>
    </collision>
  </link>
  <joint name="slot_rear right wheel_joint" type="fixed">
    <parent link="slot"/>
    <child link="rear right wheel"/>
    <origin xyz="0 0 0" rpy="0 0 0"/>
  </joint>
  <joint name="left_rear_sensor" type="continuous">
    <parent link="base_link"/>
    <child link="rear left wheel"/>
    <axis xyz="0 -1 0"/>
    <origin xyz="0 0.814 0" rpy="0 -0.536539 3.14159"/>
  </joint>
  <link name="rear left wheel">
    <visual>
      <origin xyz="0 0 0" rpy="1.570796 0 0"/>
      <geometry>
        <cylinder radius="0.374" length="0.25"/>
      </geometry>
    </visual>
    <collision>
      <origin xyz="0 0 0" rpy="1.570796 0 0"/>
      <geometry>
        <cylinder radius="0.374" length="0.25"/>
      </geometry>
    </collision>
  </link>
  <joint name="slot_0_rear left wheel_joint" type="fixed">
    <parent link="slot_0"/>
    <child link="rear left wheel"/>
    <origin xyz="0 0 0" rpy="0 0 0"/>
  </joint>
</robot>
